When I try to generate a request I get the following error:

```
[09/Sep/2025 10:24:40] "GET /generate_request/8 HTTP/1.1" 500 -
Traceback (most recent call last):
  File "/Users/kyle/.pyenv/versions/3.12.7/lib/python3.12/site-packages/flask/app.py", line 1536, in __call__
    return self.wsgi_app(environ, start_response)
           ^^^^^^^^^^^^^^^^^^^^^^^^^^^^^^^^^^^^^^
  File "/Users/kyle/.pyenv/versions/3.12.7/lib/python3.12/site-packages/werkzeug/middleware/proxy_fix.py", line 183, in __call__
    return self.app(environ, start_response)
           ^^^^^^^^^^^^^^^^^^^^^^^^^^^^^^^^^
  File "/Users/kyle/.pyenv/versions/3.12.7/lib/python3.12/site-packages/flask/app.py", line 1514, in wsgi_app
    response = self.handle_exception(e)
               ^^^^^^^^^^^^^^^^^^^^^^^^
  File "/Users/kyle/.pyenv/versions/3.12.7/lib/python3.12/site-packages/flask/app.py", line 1511, in wsgi_app
    response = self.full_dispatch_request()
               ^^^^^^^^^^^^^^^^^^^^^^^^^^^^
  File "/Users/kyle/.pyenv/versions/3.12.7/lib/python3.12/site-packages/flask/app.py", line 919, in full_dispatch_request
    rv = self.handle_user_exception(e)
         ^^^^^^^^^^^^^^^^^^^^^^^^^^^^^
  File "/Users/kyle/.pyenv/versions/3.12.7/lib/python3.12/site-packages/flask/app.py", line 917, in full_dispatch_request
    rv = self.dispatch_request()
         ^^^^^^^^^^^^^^^^^^^^^^^
  File "/Users/kyle/.pyenv/versions/3.12.7/lib/python3.12/site-packages/flask/app.py", line 902, in dispatch_request
    return self.ensure_sync(self.view_functions[rule.endpoint])(**view_args)  # type: ignore[no-any-return]
           ^^^^^^^^^^^^^^^^^^^^^^^^^^^^^^^^^^^^^^^^^^^^^^^^^^^^^^^^^^^^^^^^^^^^^^^^^^^^^^^^^^^^^^^^^^^^^^^^
  File "/Users/kyle/projects/clients/ext001/rosterwatch/routes.py", line 371, in generate_request
    request_letter = open_records_service.generate_request_letter(change_data, institution_data)
                     ^^^^^^^^^^^^^^^^^^^^^^^^^^^^^^^^^^^^^^^^^^^^^^^^^^^^^^^^^^^^^^^^^^^^^^^^^^^
  File "/Users/kyle/projects/clients/ext001/rosterwatch/open_records_service.py", line 56, in generate_request_letter
    state_info = self.get_state_info(institution.get('state', ''))
                 ^^^^^^^^^^^^^^^^^^^^^^^^^^^^^^^^^^^^^^^^^^^^^^^^^
  File "/Users/kyle/projects/clients/ext001/rosterwatch/open_records_service.py", line 17, in get_state_info
    return self.state_info.get(state_code.upper())
                               ^^^^^^^^^^^^^^^^^^^
AttributeError: 'NoneType' object has no attribute 'upper'
```